from django.contrib.auth import get_user_model
from rest_framework import serializers
from rest_framework.relations import SlugRelatedField
from rest_framework.validators import UniqueTogetherValidator

from posts.models import Comment, Follow, Group, Post

User = get_user_model()


class PostSerializer(serializers.ModelSerializer):
    """Сериализатор для модели Post."""
    author = SlugRelatedField(
        slug_field='username',
        read_only=True
    )

    class Meta:
        model = Post
        fields = '__all__'


class CommentSerializer(serializers.ModelSerializer):
    """Сериализатор для модели Comment."""
    author = serializers.SlugRelatedField(
        read_only=True,
        slug_field='username'
    )

    class Meta:
        model = Comment
        fields = '__all__'
        read_only_fields = ('post',)


class GroupSerializer(serializers.ModelSerializer):
    """Сериализатор для модели Group."""

    class Meta:
        model = Group
        fields = '__all__'


class FollowSerializer(serializers.ModelSerializer):
    """Сериализатор для модели Follow."""
    user = serializers.SlugRelatedField(
        read_only=True,
        slug_field='username',
        default=serializers.CurrentUserDefault()
    )

    following = serializers.SlugRelatedField(
        slug_field='username',
        queryset=User.objects.all()
    )

    class Meta:
        model = Follow
        fields = ('user', 'following')
        validators = (
            UniqueTogetherValidator(
                queryset=Follow.objects.all(),
                fields=('user', 'following'),
                message='Подписка уже существует'
            ),
        )

    def validate_following(self, following):
        if self.context['request'].user == following:
            raise serializers.ValidationError(
                'Нельзя подписаться на самого себя')
        return following
